.\"Generated by db2man.xsl. Don't modify this, modify the source.
.de Sh \" Subsection
.br
.if t .Sp
.ne 5
.PP
\fB\\$1\fR
.PP
..
.de Sp \" Vertical space (when we can't use .PP)
.if t .sp .5v
.if n .sp
..
.de Ip \" List item
.br
.ie \\n(.$>=3 .ne \\$3
.el .ne 3
.IP "\\$1" \\$2
..
.TH "FUNCTION THROW_" 3 "" "" ""
.SH "NAME"
boost::container::throw_logic_error
.SH "SYNOPSIS"
.\" throw_logic_error: Function throw_logic_error
.\" Function throw_logic_error: throw_logic_error

.sp
.nf
// In header: <boost/container/throw_exception\&.hpp>


void throw_logic_error(const char * str);
.fi
.SH "DESCRIPTION"
.PP
Exception callback called by Boost\&.Container to report errors in the internal logical of the program, such as violation of logical preconditions or class invariants\&.

.sp
.RS 4
.ie n \{\
\h'-04'&#8226;\h'+03'\c
.\}
.el \{\
.sp -1
.IP \(bu 2.3
.\}
If BOOST_NO_EXCEPTIONS is NOT defined
std::logic_error(str)
is thrown\&.
.sp

.RE

.sp
.RS 4
.ie n \{\
\h'-04'&#8226;\h'+03'\c
.\}
.el \{\
.sp -1
.IP \(bu 2.3
.\}
If BOOST_NO_EXCEPTIONS is defined and BOOST_CONTAINER_USER_DEFINED_THROW_CALLBACKS is NOT defined
BOOST_ASSERT_MSG(!"boost::container logic_error thrown", str)
is called and
std::abort()
if the former returns\&.
.sp

.RE

.sp
.RS 4
.ie n \{\
\h'-04'&#8226;\h'+03'\c
.\}
.el \{\
.sp -1
.IP \(bu 2.3
.\}
If BOOST_NO_EXCEPTIONS and BOOST_CONTAINER_USER_DEFINED_THROW_CALLBACKS are defined the user must provide an implementation and the function should not return\&.
.RE
.sp
.RE


